Avec ce code :
```py
    async def end(self, smooth=True):
        print("Je rentre dans la fonction END et j'envoie dans la blockchain")
        
        # Informations à envoyer à l'API blockchain
        tournament_id = 70
        winner = 'Gagnant'
        loser = 'Perdant'
        winner_score = 12
        loser_score = 34

        # URL de l'API pour l'enregistrement
        # url='http://chat:8000/api/v1/relations/blocked/'
        url = "http://blockchain:8000/register_match/"  # Remplace avec l'URL correcte de l'API

        # Construire les données du match
        data = {
            'tournament_id': tournament_id,
            'winner': winner,
            'loser': loser,
            'winner_score': winner_score,
            'loser_score': loser_score
        }

        # Envoi du POST en asynchrone à l'API
        async with httpx.AsyncClient() as client:
            try:
                response = await client.post(url, json=data)

                if response.status_code == 200:
                    print("Le match a été envoyé à l'API blockchain avec succès.")
                else:
                    print(f"Échec de l'envoi à l'API blockchain : {response.text}")

            except Exception as e:
                error_message = "Erreur lors de l'envoi à l'API blockchain :\n"
                error_message += f"Type d'erreur : {type(e).__name__}\n"
                error_message += f"Message d'erreur : {str(e)}\n"
                error_message += "Traceback complet :\n"
                error_message += traceback.format_exc()
                print(error_message, file=sys.stderr)
                print("\nVariables locales au moment de l'erreur :")
                for name, value in locals().items():
                    print(f"{name} = {value}")

        await self.match_stop()
        await super()._end()
```
J'ai cet erreur :
```
Je rentre dans la fonction END et j'envoie dans la blockchain
Erreur lors de l'envoi à l'API blockchain :
Type d'erreur : ReadTimeout
Message d'erreur : 
Traceback complet :
Traceback (most recent call last):
  File "/usr/local/lib/python3.12/site-packages/httpx/_transports/default.py", line 69, in map_httpcore_exceptions
    yield
  File "/usr/local/lib/python3.12/site-packages/httpx/_transports/default.py", line 373, in handle_async_request
    resp = await self._pool.handle_async_request(req)
           ^^^^^^^^^^^^^^^^^^^^^^^^^^^^^^^^^^^^^^^^^^
  File "/usr/local/lib/python3.12/site-packages/httpcore/_async/connection_pool.py", line 216, in handle_async_request
    raise exc from None
  File "/usr/local/lib/python3.12/site-packages/httpcore/_async/connection_pool.py", line 196, in handle_async_request
    response = await connection.handle_async_request(

Variables locales au moment de l'erreur :
self = <game.lobby.LocalTournament object at 0x7f0b4e12e210>
smooth = False
tournament_id = 70
winner = Gagnant
loser = Perdant
winner_score = 12
loser_score = 34
               ^^^^^^^^^^^^^^^^^^^^^^^^^^^^^^^^^^^^^^
  File "/usr/local/lib/python3.12/site-packages/httpcore/_async/connection.py", line 101, in handle_async_request
    return await self._connection.handle_async_request(request)
           ^^^^^^^^^^^^^^^^^^^^^^^^^^^^^^^^^^^^^^^^^^^^^^^^^^^^
  File "/usr/local/lib/python3.12/site-packages/httpcore/_async/http11.py", line 143, in handle_async_request
    raise exc
  File "/usr/local/lib/python3.12/site-packages/httpcore/_async/http11.py", line 113, in handle_async_request
    ) = await self._receive_response_headers(**kwargs)
        ^^^^^^^^^^^^^^^^^^^^^^^^^^^^^^^^^^^^^^^^^^^^^^
  File "/usr/local/lib/python3.12/site-packages/httpcore/_async/http11.py", line 186, in _receive_response_headers
    event = await self._receive_event(timeout=timeout)
            ^^^^^^^^^^^^^^^^^^^^^^^^^^^^^^^^^^^^^^^^^^
  File "/usr/local/lib/python3.12/site-packages/httpcore/_async/http11.py", line 224, in _receive_event
    data = await self._network_stream.read(
           ^^^^^^^^^^^^^^^^^^^^^^^^^^^^^^^^
  File "/usr/local/lib/python3.12/site-packages/httpcore/_backends/anyio.py", line 32, in read
    with map_exceptions(exc_map):
  File "/usr/local/lib/python3.12/contextlib.py", line 158, in __exit__
    self.gen.throw(value)
  File "/usr/local/lib/python3.12/site-packages/httpcore/_exceptions.py", line 14, in map_exceptions
    raise to_exc(exc) from exc
httpcore.ReadTimeout

url = http://blockchain:8000/register_match/
data = {'tournament_id': 70, 'winner': 'Gagnant', 'loser': 'Perdant', 'winner_score': 12, 'loser_score': 34}
client = <httpx.AsyncClient object at 0x7f0b4dc07e30>
e = 
error_message = Erreur lors de l'envoi à l'API blockchain :
Type d'erreur : ReadTimeout
Message d'erreur : 
Traceback complet :
Traceback (most recent call last):
  File "/usr/local/lib/python3.12/site-packages/httpx/_transports/default.py", line 69, in map_httpcore_exceptions
    yield
  File "/usr/local/lib/python3.12/site-packages/httpx/_transports/default.py", line 373, in handle_async_request
    resp = await self._pool.handle_async_request(req)
           ^^^^^^^^^^^^^^^^^^^^^^^^^^^^^^^^^^^^^^^^^^
  File "/usr/local/lib/python3.12/site-packages/httpcore/_async/connection_pool.py", line 216, in handle_async_request
    raise exc from None
  File "/usr/local/lib/python3.12/site-packages/httpcore/_async/connection_pool.py", line 196, in handle_async_request
    response = await connection.handle_async_request(
               ^^^^^^^^^^^^^^^^^^^^^^^^^^^^^^^^^^^^^^
  File "/usr/local/lib/python3.12/site-packages/httpcore/_async/connection.py", line 101, in handle_async_request
    return await self._connection.handle_async_request(request)
           ^^^^^^^^^^^^^^^^^^^^^^^^^^^^^^^^^^^^^^^^^^^^^^^^^^^^
  File "/usr/local/lib/python3.12/site-packages/httpcore/_async/http11.py", line 143, in handle_async_request
    raise exc
  File "/usr/local/lib/python3.12/site-packages/httpcore/_async/http11.py", line 113, in handle_async_request
    ) = await self._receive_response_headers(**kwargs)
        ^^^^^^^^^^^^^^^^^^^^^^^^^^^^^^^^^^^^^^^^^^^^^^
  File "/usr/local/lib/python3.12/site-packages/httpcore/_async/http11.py", line 186, in _receive_response_headers
    event = await self._receive_event(timeout=timeout)
            ^^^^^^^^^^^^^^^^^^^^^^^^^^^^^^^^^^^^^^^^^^
  File "/usr/local/lib/python3.12/site-packages/httpcore/_async/http11.py", line 224, in _receive_event
    data = await self._network_stream.read(
           ^^^^^^^^^^^^^^^^^^^^^^^^^^^^^^^^
  File "/usr/local/lib/python3.12/site-packages/httpcore/_backends/anyio.py", line 32, in read
    with map_exceptions(exc_map):
  File "/usr/local/lib/python3.12/contextlib.py", line 158, in __exit__
    self.gen.throw(value)
  File "/usr/local/lib/python3.12/site-packages/httpcore/_exceptions.py", line 14, in map_exceptions
    raise to_exc(exc) from exc
httpcore.ReadTimeout

The above exception was the direct cause of the following exception:

Traceback (most recent call last):
  File "/app/game/lobby.py", line 297, in end
    response = await client.post(url, json=data)
               ^^^^^^^^^^^^^^^^^^^^^^^^^^^^^^^^^
  File "/usr/local/lib/python3.12/site-packages/httpx/_client.py", line 1892, in post
    return await self.request(
           ^^^^^^^^^^^^^^^^^^^
  File "/usr/local/lib/python3.12/site-packages/httpx/_client.py", line 1574, in request
    return await self.send(request, auth=auth, follow_redirects=follow_redirects)
           ^^^^^^^^^^^^^^^^^^^^^^^^^^^^^^^^^^^^^^^^^^^^^^^^^^^^^^^^^^^^^^^^^^^^^^
  File "/usr/local/lib/python3.12/site-packages/httpx/_client.py", line 1661, in send
    response = await self._send_handling_auth(
               ^^^^^^^^^^^^^^^^^^^^^^^^^^^^^^^
  File "/usr/local/lib/python3.12/site-packages/httpx/_client.py", line 1689, in _send_handling_auth
    response = await self._send_handling_redirects(
               ^^^^^^^^^^^^^^^^^^^^^^^^^^^^^^^^^^^^
  File "/usr/local/lib/python3.12/site-packages/httpx/_client.py", line 1726, in _send_handling_redirects
    response = await self._send_single_request(request)
               ^^^^^^^^^^^^^^^^^^^^^^^^^^^^^^^^^^^^^^^^
  File "/usr/local/lib/python3.12/site-packages/httpx/_client.py", line 1763, in _send_single_request
    response = await transport.handle_async_request(request)
               ^^^^^^^^^^^^^^^^^^^^^^^^^^^^^^^^^^^^^^^^^^^^^
  File "/usr/local/lib/python3.12/site-packages/httpx/_transports/default.py", line 372, in handle_async_request
    with map_httpcore_exceptions():
The above exception was the direct cause of the following exception:
  File "/usr/local/lib/python3.12/contextlib.py", line 158, in __exit__

    self.gen.throw(value)
Traceback (most recent call last):
  File "/usr/local/lib/python3.12/site-packages/httpx/_transports/default.py", line 86, in map_httpcore_exceptions
  File "/app/game/lobby.py", line 297, in end
    raise mapped_exc(message) from exc
httpx.ReadTimeout
    response = await client.post(url, json=data)

               ^^^^^^^^^^^^^^^^^^^^^^^^^^^^^^^^^
__class__ = <class 'game.lobby.LocalTournament'>
  File "/usr/local/lib/python3.12/site-packages/httpx/_client.py", line 1892, in post
    return await self.request(
           ^^^^^^^^^^^^^^^^^^^
  File "/usr/local/lib/python3.12/site-packages/httpx/_client.py", line 1574, in request
    return await self.send(request, auth=auth, follow_redirects=follow_redirects)
           ^^^^^^^^^^^^^^^^^^^^^^^^^^^^^^^^^^^^^^^^^^^^^^^^^^^^^^^^^^^^^^^^^^^^^^
  File "/usr/local/lib/python3.12/site-packages/httpx/_client.py", line 1661, in send
    response = await self._send_handling_auth(
               ^^^^^^^^^^^^^^^^^^^^^^^^^^^^^^^
  File "/usr/local/lib/python3.12/site-packages/httpx/_client.py", line 1689, in _send_handling_auth
    response = await self._send_handling_redirects(
               ^^^^^^^^^^^^^^^^^^^^^^^^^^^^^^^^^^^^
  File "/usr/local/lib/python3.12/site-packages/httpx/_client.py", line 1726, in _send_handling_redirects
    response = await self._send_single_request(request)
               ^^^^^^^^^^^^^^^^^^^^^^^^^^^^^^^^^^^^^^^^
  File "/usr/local/lib/python3.12/site-packages/httpx/_client.py", line 1763, in _send_single_request
    response = await transport.handle_async_request(request)
               ^^^^^^^^^^^^^^^^^^^^^^^^^^^^^^^^^^^^^^^^^^^^^
  File "/usr/local/lib/python3.12/site-packages/httpx/_transports/default.py", line 372, in handle_async_request
    with map_httpcore_exceptions():
  File "/usr/local/lib/python3.12/contextlib.py", line 158, in __exit__
    self.gen.throw(value)
  File "/usr/local/lib/python3.12/site-packages/httpx/_transports/default.py", line 86, in map_httpcore_exceptions
    raise mapped_exc(message) from exc
httpx.ReadTimeout

```